<?xml version="1.0" ?>
<!-- =================================================================================== -->
<!-- |    This document was autogenerated by xacro from /home/dangtran/Desktop/caster_description/urdf/caster.urdf.xacro | -->
<!-- |    EDITING THIS FILE BY HAND IS NOT RECOMMENDED                                 | -->
<!-- =================================================================================== -->
<robot description="iqr caster robot" name="caster_robot"
    xmlns:xacro="http://www.ros.org/wiki/xacro">
    <!-- base footprint -->
    <link name="base_footprint">
        <origin rpy="0 0 0" xyz="0 0 0"/>
        <!-- <xacro:default_inertial mass="0.0001" /> -->
    </link>
    <!-- base link -->
    <link name="base_link">
        <visual>
            <origin rpy="0 0 0" xyz="0 0 0"/>
            <geometry>
                <mesh filename="mesh/caster_base.stl"/>
            </geometry>
            <material name="">
                <color rgba="0.98 1.0 0.94 1.0"/>
            </material>
        </visual>
        <inertial>
            <mass value="10"/>
            <inertia ixx="1.0" ixy="0.0" ixz="0.0" iyy="1.0" iyz="0.0" izz="1.0"/>
        </inertial>
    </link>
    <joint name="base_link_joint" type="fixed">
        <origin rpy="0 0 0" xyz="0 0 0.030"/>
        <parent link="base_footprint"/>
        <child link="base_link"/>
    </joint>
    <!-- IMU link -->
    <link name="imu_link"/>
    <joint name="imu_link_joint" type="fixed">
        <origin rpy="0 0 0" xyz="0 0 0"/>
        <parent link="base_link"/>
        <child link="imu_link"/>
    </joint>
    <!-- Laser link -->
    <link name="laser_link"/>
    <joint name="laser_link_joint" type="fixed">
        <origin rpy="0 0 0" xyz="0.2301 0 0.147"/>
        <parent link="base_link"/>
        <child link="laser_link"/>
    </joint>
    <!-- Laser link 2 (rplidar) -->
    <link name="laser_link2"/>
    <joint name="laser_link_joint2" type="fixed">
        <origin rpy="0 0 3.14159265359" xyz="0.01525 0 0.2115"/>
        <parent link="base_link"/>
        <child link="laser_link2"/>
    </joint>
    <link name="drive_wheel_left_link">
        <!-- xacro:default_inertial mass="0.1" / -->
        <visual>
            <origin rpy="0 0 0.0" xyz="0 0 0"/>
            <geometry>
                <mesh filename="mesh/drive_wheel.stl"/>
            </geometry>
            <material name="">
                <color rgba="0.30 0.30 0.30 1"/>
            </material>
        </visual>
        <collision>
            <origin rpy="1.57079632679 0 0" xyz="0 0 0"/>
            <geometry>
                <cylinder length="0.035" radius="0.075"/>
            </geometry>
        </collision>
    </link>
    <joint name="drive_wheel_left_joint" type="continuous">
        <origin rpy="0 0 0" xyz="0 0.2087 0.045"/>
        <parent link="base_link"/>
        <child link="drive_wheel_left_link"/>
        <axis rpy="0 0 0" xyz="0 1 0"/>
    </joint>
    <link name="drive_wheel_right_link">
        <!-- xacro:default_inertial mass="0.1" / -->
        <visual>
            <origin rpy="0 0 3.14159265359" xyz="0 0 0"/>
            <geometry>
                <mesh filename="mesh/drive_wheel.stl"/>
            </geometry>
            <material name="">
                <color rgba="0.30 0.30 0.30 1"/>
            </material>
        </visual>
        <collision>
            <origin rpy="1.57079632679 0 0" xyz="0 0 0"/>
            <geometry>
                <cylinder length="0.035" radius="0.075"/>
            </geometry>
        </collision>
    </link>
    <joint name="drive_wheel_right_joint" type="continuous">
        <origin rpy="0 0 0" xyz="0 -0.2087 0.045"/>
        <parent link="base_link"/>
        <child link="drive_wheel_right_link"/>
        <axis rpy="0 0 0" xyz="0 1 0"/>
    </joint>
    <link name="support_wheel_front_left_link">
        <visual>
            <origin rpy="0 0 0" xyz="0 0 0"/>
            <geometry>
                <mesh filename="mesh/support_wheel.stl"/>
            </geometry>
            <material name="">
                <color rgba="0.3 0.3 0.3 1.0"/>
            </material>
        </visual>
        <inertial>
            <mass value="0.1"/>
            <inertia ixx="1.0" ixy="0.0" ixz="0.0" iyy="1.0" iyz="0.0" izz="1.0"/>
        </inertial>
    </link>
    <joint name="support_wheel_front_left_joint" type="fixed">
        <origin rpy="0 0 0" xyz="0.185 0.150 0.037"/>
        <parent link="base_link"/>
        <child link="support_wheel_front_left_link"/>
        <!-- <axis xyz="0 0 1" /> -->
    </joint>
    <link name="support_wheel_front_right_link">
        <visual>
            <origin rpy="0 0 0" xyz="0 0 0"/>
            <geometry>
                <mesh filename="mesh/support_wheel.stl"/>
            </geometry>
            <material name="">
                <color rgba="0.3 0.3 0.3 1.0"/>
            </material>
        </visual>
        <inertial>
            <mass value="0.1"/>
            <inertia ixx="1.0" ixy="0.0" ixz="0.0" iyy="1.0" iyz="0.0" izz="1.0"/>
        </inertial>
    </link>
    <joint name="support_wheel_front_right_joint" type="fixed">
        <origin rpy="0 0 0" xyz="0.185 -0.150 0.037"/>
        <parent link="base_link"/>
        <child link="support_wheel_front_right_link"/>
        <!-- <axis xyz="0 0 1" /> -->
    </joint>
    <link name="support_wheel_rear_left_link">
        <visual>
            <origin rpy="0 0 0" xyz="0 0 0"/>
            <geometry>
                <mesh filename="mesh/support_wheel.stl"/>
            </geometry>
            <material name="">
                <color rgba="0.3 0.3 0.3 1.0"/>
            </material>
        </visual>
        <inertial>
            <mass value="0.1"/>
            <inertia ixx="1.0" ixy="0.0" ixz="0.0" iyy="1.0" iyz="0.0" izz="1.0"/>
        </inertial>
    </link>
    <joint name="support_wheel_rear_left_joint" type="fixed">
        <origin rpy="0 0 0" xyz="-0.185 0.150 0.037"/>
        <parent link="base_link"/>
        <child link="support_wheel_rear_left_link"/>
        <!-- <axis xyz="0 0 1" /> -->
    </joint>
    <link name="support_wheel_rear_right_link">
        <visual>
            <origin rpy="0 0 0" xyz="0 0 0"/>
            <geometry>
                <mesh filename="mesh/support_wheel.stl"/>
            </geometry>
            <material name="">
                <color rgba="0.3 0.3 0.3 1.0"/>
            </material>
        </visual>
        <inertial>
            <mass value="0.1"/>
            <inertia ixx="1.0" ixy="0.0" ixz="0.0" iyy="1.0" iyz="0.0" izz="1.0"/>
        </inertial>
    </link>
    <joint name="support_wheel_rear_right_joint" type="fixed">
        <origin rpy="0 0 0" xyz="-0.185 -0.150 0.037"/>
        <parent link="base_link"/>
        <child link="support_wheel_rear_right_link"/>
        <!-- <axis xyz="0 0 1" /> -->
    </joint>
    <link name="ultrasonic_front_left_link">
        <visual>
            <origin rpy="0 1.57079632679 0" xyz="0 0 0"/>
            <geometry>
                <cylinder length="0.01" radius="0.01"/>
            </geometry>
            <material name="">
                <color rgba="0.3 0.3 0.3 1.0"/>
            </material>
        </visual>
        <inertial>
            <mass value="0.1"/>
            <inertia ixx="1.0" ixy="0.0" ixz="0.0" iyy="1.0" iyz="0.0" izz="1.0"/>
        </inertial>
    </link>
    <joint name="ultrasonic_front_left_joint" type="fixed">
        <origin rpy="0 0 0.2618" xyz="0.26248 0.0704 0.0245"/>
        <parent link="base_link"/>
        <child link="ultrasonic_front_left_link"/>
    </joint>
    <link name="ultrasonic_front_right_link">
        <visual>
            <origin rpy="0 1.57079632679 0" xyz="0 0 0"/>
            <geometry>
                <cylinder length="0.01" radius="0.01"/>
            </geometry>
            <material name="">
                <color rgba="0.3 0.3 0.3 1.0"/>
            </material>
        </visual>
        <inertial>
            <mass value="0.1"/>
            <inertia ixx="1.0" ixy="0.0" ixz="0.0" iyy="1.0" iyz="0.0" izz="1.0"/>
        </inertial>
    </link>
    <joint name="ultrasonic_front_right_joint" type="fixed">
        <origin rpy="0 0 -0.2618" xyz="0.26248 -0.0704 0.0245"/>
        <parent link="base_link"/>
        <child link="ultrasonic_front_right_link"/>
    </joint>
    <link name="ultrasonic_rear_left_link">
        <visual>
            <origin rpy="0 1.57079632679 0" xyz="0 0 0"/>
            <geometry>
                <cylinder length="0.01" radius="0.01"/>
            </geometry>
            <material name="">
                <color rgba="0.3 0.3 0.3 1.0"/>
            </material>
        </visual>
        <inertial>
            <mass value="0.1"/>
            <inertia ixx="1.0" ixy="0.0" ixz="0.0" iyy="1.0" iyz="0.0" izz="1.0"/>
        </inertial>
    </link>
    <joint name="ultrasonic_rear_left_joint" type="fixed">
        <origin rpy="0 0 2.8798" xyz="-0.26298 0.0704 0.2095"/>
        <parent link="base_link"/>
        <child link="ultrasonic_rear_left_link"/>
    </joint>
    <link name="ultrasonic_rear_right_link">
        <visual>
            <origin rpy="0 1.57079632679 0" xyz="0 0 0"/>
            <geometry>
                <cylinder length="0.01" radius="0.01"/>
            </geometry>
            <material name="">
                <color rgba="0.3 0.3 0.3 1.0"/>
            </material>
        </visual>
        <inertial>
            <mass value="0.1"/>
            <inertia ixx="1.0" ixy="0.0" ixz="0.0" iyy="1.0" iyz="0.0" izz="1.0"/>
        </inertial>
    </link>
    <joint name="ultrasonic_rear_right_joint" type="fixed">
        <origin rpy="0 0 -2.8798" xyz="-0.26298 -0.0704 0.2095"/>
        <parent link="base_link"/>
        <child link="ultrasonic_rear_right_link"/>
    </joint>
</robot>
